Workbook

Sheet OCT (01)
A1: ‡gmvm© Imgvb wdm& | H1: ‡gmvm© Imgvb wdm&
A2: mvBb‡evW© evRvi grm Avor | H2: mvBb‡evW© evRvi grm Avor
A3: evi t | D3: ‡µwWU | F3: ZvwiL t- | H3: evi t | K3: ‡WwWU | M3: ZvwiL t-
A4: c~‡e©i K¨vk-Bb-n¨vÛ t | F4: 500000 | G4: **** | K4: D | N4: ****
D5: C | G5: =F4 -> 500000 | K5: D | N5: =M4 -> 0
D6: C | G6: =G5+F5 -> 500000 | K6: D | N6: =N5+M5 -> 0
D7: C | G7: =G6+F6 -> 500000 | K7: D | N7: =N6+M6 -> 0
D8: C | G8: =G7+F7 -> 500000 | K8: D | N8: =N7+M7 -> 0
D9: C | G9: =G8+F8 -> 500000 | K9: D | N9: =N8+M8 -> 0
D10: C | G10: =G9+F9 -> 500000 | K10: D | N10: =N9+M9 -> 0
D11: C | G11: =G10+F10 -> 500000 | K11: D | N11: =N10+M10 -> 0
D12: C | G12: =G11+F11 -> 500000 | K12: D | N12: =N11+M11 -> 0
D13: C | G13: =G12+F12 -> 500000 | K13: D | N13: =N12+M12 -> 0
D14: C | G14: =G13+F13 -> 500000 | K14: D | N14: =N13+M13 -> 0
D15: C | G15: =G14+F14 -> 500000 | K15: D | N15: =N14+M14 -> 0
D16: C | G16: =G15+F15 -> 500000 | K16: D | N16: =N15+M15 -> 0
D17: C | G17: =G16+F16 -> 500000 | K17: D | N17: =N16+M16 -> 0
... D34: C | G34: =G33+F33 -> 500000 | K34: D | N34: =N33+M33 -> 0
A35: †gvU †µwWU t | D35: =G34+F34 -> 500000 | H35: ‡gvU †WweU t | K35: =N34+M34 -> 0
A36: ‡gvU †WweU t | D36: =K35 -> 0
A37: eZ©gvb K¨vk t | D37: =D35-D36 -> 500000

Sheet OCT (2)
A1: ‡gmvm© Imgvb wdm& | H1: ‡gmvm© Imgvb wdm&
A2: mvBb‡evW© evRvi grm Avor | H2: mvBb‡evW© evRvi grm Avor
A3: evi t | D3: ‡µwWU | F3: ZvwiL t- | H3: evi t | K3: ‡WwWU | M3: ZvwiL t-
A4: c~‡e©i K¨vk-Bb-n¨vÛ t | F4: ='OCT (01)'!D37 -> 500000 | G4: **** | K4: D | N4: ****
D5: C | G5: =F4 -> 500000 | K5: D | N5: =M4 -> 0
D6: C | G6: =G5+F5 -> 500000 | K6: D | N6: =N5+M5 -> 0
D7: C | G7: =G6+F6 -> 500000 | K7: D | N7: =N6+M6 -> 0
D8: C | G8: =G7+F7 -> 500000 | K8: D | N8: =N7+M7 -> 0
D9: C | G9: =G8+F8 -> 500000 | K9: D | N9: =N8+M8 -> 0
D10: C | G10: =G9+F9 -> 500000 | K10: D | N10: =N9+M9 -> 0
D11: C | G11: =G10+F10 -> 500000 | K11: D | N11: =N10+M10 -> 0
D12: C | G12: =G11+F11 -> 500000 | K12: D | N12: =N11+M11 -> 0
D13: C | G13: =G12+F12 -> 500000 | K13: D | N13: =N12+M12 -> 0
D14: C | G14: =G13+F13 -> 500000 | K14: D | N14: =N13+M13 -> 0
D15: C | G15: =G14+F14 -> 500000 | K15: D | N15: =N14+M14 -> 0
D16: C | G16: =G15+F15 -> 500000 | K16: D | N16: =N15+M15 -> 0
D17: C | G17: =G16+F16 -> 500000 | K17: D | N17: =N16+M16 -> 0
... D34: C | G34: =G33+F33 -> 500000 | K34: D | N34: =N33+M33 -> 0
A35: †gvU †µwWU t | D35: =G34+F34 -> 500000 | H35: ‡gvU †WweU t | K35: =N34+M34 -> 0
A36: ‡gvU †WweU t | D36: =K35 -> 0
A37: eZ©gvb K¨vk t | D37: =D35-D36 -> 500000

Sheet OCT (3)
A1: ‡gmvm© Imgvb wdm& | H1: ‡gmvm© Imgvb wdm&
A2: mvBb‡evW© evRvi grm Avor | H2: mvBb‡evW© evRvi grm Avor
A3: evi t | D3: ‡µwWU | F3: ZvwiL t- | H3: evi t | K3: ‡WwWU | M3: ZvwiL t-
A4: c~‡e©i K¨vk-Bb-n¨vÛ t | F4: ='OCT (2)'!D37 -> 500000 | G4: **** | K4: D | N4: ****
D5: C | G5: =F4 -> 500000 | K5: D | N5: =M4 -> 0
D6: C | G6: =G5+F5 -> 500000 | K6: D | N6: =N5+M5 -> 0
D7: C | G7: =G6+F6 -> 500000 | K7: D | N7: =N6+M6 -> 0
D8: C | G8: =G7+F7 -> 500000 | K8: D | N8: =N7+M7 -> 0
D9: C | G9: =G8+F8 -> 500000 | K9: D | N9: =N8+M8 -> 0
D10: C | G10: =G9+F9 -> 500000 | K10: D | N10: =N9+M9 -> 0
D11: C | G11: =G10+F10 -> 500000 | K11: D | N11: =N10+M10 -> 0
D12: C | G12: =G11+F11 -> 500000 | K12: D | N12: =N11+M11 -> 0
D13: C | G13: =G12+F12 -> 500000 | K13: D | N13: =N12+M12 -> 0
D14: C | G14: =G13+F13 -> 500000 | K14: D | N14: =N13+M13 -> 0
D15: C | G15: =G14+F14 -> 500000 | K15: D | N15: =N14+M14 -> 0
D16: C | G16: =G15+F15 -> 500000 | K16: D | N16: =N15+M15 -> 0
D17: C | G17: =G16+F16 -> 500000 | K17: D | N17: =N16+M16 -> 0
... D34: C | G34: =G33+F33 -> 500000 | K34: D | N34: =N33+M33 -> 0
A35: †gvU †µwWU t | D35: =G34+F34 -> 500000 | H35: ‡gvU †WweU t | K35: =N34+M34 -> 0
A36: ‡gvU †WweU t | D36: =K35 -> 0
A37: eZ©gvb K¨vk t | D37: =D35-D36 -> 500000

Sheet OCT (4)
A1: ‡gmvm© Imgvb wdm& | H1: ‡gmvm© Imgvb wdm&
A2: mvBb‡evW© evRvi grm Avor | H2: mvBb‡evW© evRvi grm Avor
A3: evi t | C3: ïµevi | D3: ‡µwWU | F3: ZvwiL t- | G3: 45569 | H3: evi t | J3: ïµevi | K3: ‡WwWU | M3: ZvwiL t- | N3: 45569
A4: c~‡e©i K¨vk-Bb-n¨vÛ t | F4: ='OCT (3)'!D37 -> 500000 | G4: **** | I4: 1 bs- | J4: bM` weµq-- | K4: D | L4: 16 bs- | M4: 6900 | N4: ****
C5: Kwgkb-- | D5: C | F5: 6300 | G5: =F4 -> 500000 | I5: 2 bs- | J5: BKivg-- | K5: D | L5: 14 bs- | M5: 2640 | N5: =M4 -> 6900
C6: mwgwZ-- | D6: C | F6: 90 | G6: =G5+F5 -> 506300 | I6: 3 bs- | J6: kvwKj -- | K6: D | L6: 12 bs- | M6: 3640 | N6: =N5+M5 -> 9540
C7: gmwR`-- | D7: C | F7: 90 | G7: =G6+F6 -> 506390 | I7: 4 bs- | J7: Avt iv¾vK-- | K7: D | L7: 01 bs- | M7: 20510 | N7: =N6+M6 -> 13180
A8: D | B8: 1 bs | C8: bM` Rgv-- | D8: C | F8: 6900 | G8: =G7+F7 -> 506480 | I8: 5 bs- | J8: wRKz-- | K8: D | L8: 02 bs- | M8: 24310 | N8: =N7+M7 -> 33690
A9: D | B9: 3bs | C9: kvwKj-- | D9: C | E9: 12 | F9: 3640 | G9: =G8+F8 -> 513380 | I9: 6 bs- | J9: Av‡bvqvi-- | K9: D | L9: 13 bs- | M9: 1100 | N9: =N8+M8 -> 58000
A10: D | B10: 12bs | C10: ‡ejv‡qZ-- | D10: C | E10: 8 | F10: 13430 | G10: =G9+F9 -> 517020 | I10: 7 bs- | J10: ‡gv¯Ídv-- | K10: D | L10: 03 bs- | M10: 18920 | N10: =N9+M9 -> 59100
D11: C | G11: =G10+F10 -> 530450 | I11: 8 bs- | J11: ‡gvZv‡je-- | K11: D | L11: 04 bs- | M11: 24720 | N11: =N10+M10 -> 78020
D12: C | G12: =G11+F11 -> 530450 | I12: 9 bs- | J12: eKzj fvB-- | K12: D | L12: 05 bs- | M12: 1750 | N12: =N11+M11 -> 102740
D13: C | G13: =G12+F12 -> 530450 | I13: 10 bs- | J13: ‡mvnvM-- | K13: D | L13: 06 bs- | M13: 4890 | N13: =N12+M12 -> 104490
D14: C | G14: =G13+F13 -> 530450 | I14: 11 bs- | J14: jyrdvi-- | K14: D | L14: 07 bs- | M14: 19280 | N14: =N13+M13 -> 109380
D15: C | G15: =G14+F14 -> 530450 | I15: 12 bs- | J15: ‡ejv‡qZ-- | K15: D | L15: 08 bs- | M15: 13430 | N15: =N14+M14 -> 128660
D16: C | G16: =G15+F15 -> 530450 | I16: 13 bs- | J16: AvjgwMi-- | K16: D | L16: 09 bs- | M16: 2780 | N16: =N15+M15 -> 142090
D17: C | G17: =G16+F16 -> 530450 | I17: 14 bs- | J17: gnvwmb-- | K17: D | L17: 10 bs- | M17: 2160 | N17: =N16+M16 -> 144870
D18: C | G18: =G17+F17 -> 530450 | I18: 15 bs- | J18: ‡gvt Avmjvg-- | K18: D | L18: 11 bs- | M18: 6610 | N18: =N17+M17 -> 147030
D19: C | G19: =G18+F18 -> 530450 | I19: 16 bs- | J19: ‡gvt gvgyb-- | K19: D | L19: 15 bs- | M19: 3310 | N19: =N18+M18 -> 153640
D20: C | G20: =G19+F19 -> 530450 | J20: eKwkm-- | K20: D | M20: 450 | N20: =N19+M19 -> 156950
D21: C | G21: =G20+F20 -> 530450 | J21: bv¯Ív LiP-- | K21: D | M21: 200 | N21: =N20+M20 -> 157400
D22: C | G22: =G21+F21 -> 530450 | J22: eªvm µq-- | K22: D | M22: 50 | N22: =N21+M21 -> 157600
D23: C | G23: =G22+F22 -> 530450 | J23: K¨vk mU / †jvKgvb-- | K23: D | M23: 950 | N23: =N22+M22 -> 157650
D24: C | G24: =G23+F23 -> 530450 | K24: D | N24: =N23+M23 -> 158600
D25: C | G25: =G24+F24 -> 530450 | K25: D | N25: =N24+M24 -> 158600
D26: C | G26: =G25+F25 -> 530450 | K26: D | N26: =N25+M25 -> 158600
D27: C | G27: =G26+F26 -> 530450 | K27: D | N27: =N26+M26 -> 158600
D28: C | G28: =G27+F27 -> 530450 | K28: D | N28: =N27+M27 -> 158600
D29: C | G29: =G28+F28 -> 530450 | K29: D | N29: =N28+M28 -> 158600
D30: C | G30: =G29+F29 -> 530450 | K30: D | N30: =N29+M29 -> 158600
D31: C | G31: =G30+F30 -> 530450 | K31: D | N31: =N30+M30 -> 158600
D32: C | G32: =G31+F31 -> 530450 | K32: D | N32: =N31+M31 -> 158600
D33: C | G33: =G32+F32 -> 530450 | K33: D | N33: =N32+M32 -> 158600
D34: C | G34: =G33+F33 -> 530450 | K34: D | N34: =N33+M33 -> 158600
A35: †gvU †µwWU t | D35: =G34+F34 -> 530450 | H35: ‡gvU †WweU t | K35: =N34+M34 -> 158600
A36: ‡gvU †WweU t | D36: =K35 -> 158600
A37: eZ©gvb K¨vk t | D37: =D35-D36 -> 371850

Sheet OCT (5)
A1: ‡gmvm© Imgvb wdm& | H1: ‡gmvm© Imgvb wdm&
A2: mvBb‡evW© evRvi grm Avor | H2: mvBb‡evW© evRvi grm Avor
A3: evi t | C3: kwbevi | D3: ‡µwWU | F3: ZvwiL t- | G3: 45570 | H3: evi t | J3: kwbevi | K3: ‡WwWU | M3: ZvwiL t- | N3: 45570
A4: c~‡e©i K¨vk-Bb-n¨vÛ t | F4: ='OCT (4)'!D37 -> 371850 | G4: **** | J4: eKwkm-- | K4: D | M4: 300 | N4: ****
C5: Kwgkb- | D5: C | F5: 3380 | G5: =F4 -> 371850 | J5: ÷vd bv¯Ív- | K5: D | M5: 400 | N5: =M4 -> 300
C6: gmwR`- | D6: C | F6: 60 | G6: =G5+F5 -> 375230 | I6: 17 bs | J6: RvwKi PvPv-- | K6: D | M6: 9510 | N6: =N5+M5 -> 700
C7: mwgwZ- | D7: C | F7: 50 | G7: =G6+F6 -> 375290 | I7: 18 bs | J7: wRKz fvB-- | K7: D | M7: 28100 | N7: =N6+M6 -> 10210
C8: bM` weµq- | D8: C | F8: 750 | G8: =G7+F7 -> 375340 | I8: 19 bs | J8: eKzj fvB-- | K8: D | M8: 7840 | N8: =N7+M7 -> 38310
C9: jytdi Rgv- | D9: C | F9: 19280 | G9: =G8+F8 -> 376090 | I9: 20 bs | J9: bM`-- | K9: D | M9: 750 | N9: =N8+M8 -> 46150
C10: AvjgwMi Rgv- | D10: C | F10: 2780 | G10: =G9+F9 -> 395370 | I10: 21 bs | J10: kvwKj-- | K10: D | M10: 2700 | N10: =N9+M9 -> 46900
C11: Avmjvg Rgv- | D11: C | F11: 6610 | G11: =G10+F10 -> 398150 | I11: 22 bs | J11: ûgvqyb-- | K11: D | M11: 1390 | N11: =N10+M10 -> 49600
C12: GKivg Rgv- | D12: C | F12: 2640 | G12: =G11+F11 -> 404760 | I12: 23 bs | J12: jytdvi-- | K12: D | M12: 5240 | N12: =N11+M11 -> 50990
C13: ‡mvnvM Rgv- | D13: C | F13: 4890 | G13: =G12+F12 -> 407400 | I13: 24 bs | J13: gwZb-- | K13: D | M13: 1450 | N13: =N12+M12 -> 56230
C14: gvgyb Rgv- | D14: C | F14: 3310 | G14: =G13+F13 -> 412290 | I14: 25 bs | J14: Avmjvg-- | K14: D | M14: 15540 | N14: =N13+M13 -> 57680
C15: ‡gvZv‡je Rgv- | D15: C | F15: 10000 | G15: =G14+F14 -> 415600 | I15: 26 bs | J15: ‡ejv‡qZ-- | K15: D | M15: 10280 | N15: =N14+M14 -> 73220
D16: C | G16: =G15+F15 -> 425600 | I16: 27 bs | J16: ‡ngv‡qZ-- | K16: D | M16: 1900 | N16: =N15+M15 -> 83500
D17: C | G17: =G16+F16 -> 425600 | K17: D | N17: =N16+M16 -> 85400
D18: C | G18: =G17+F17 -> 425600 | K18: D | N18: =N17+M17 -> 85400
D19: C | G19: =G18+F18 -> 425600 | K19: D | N19: =N18+M18 -> 85400
D20: C | G20: =G19+F19 -> 425600 | K20: D | N20: =N19+M19 -> 85400
D21: C | G21: =G20+F20 -> 425600 | K21: D | N21: =N20+M20 -> 85400
D22: C | G22: =G21+F21 -> 425600 | K22: D | N22: =N21+M21 -> 85400
D23: C | G23: =G22+F22 -> 425600 | J23: c~‡e©i LiP-1650 | K23: D | N23: =N22+M22 -> 85400
D24: C | G24: =G23+F23 -> 425600 | J24: AvR‡Ki LiP-700 | K24: D | N24: =N23+M23 -> 85400
D25: C | G25: =G24+F24 -> 425600 | J25: ‡gvU eKwkm= 2350 | K25: D | N25: =N24+M24 -> 85400
D26: C | G26: =G25+F25 -> 425600 | K26: D | N26: =N25+M25 -> 85400
D27: C | G27: =G26+F26 -> 425600 | K27: D | N27: =N26+M26 -> 85400
D28: C | G28: =G27+F27 -> 425600 | K28: D | N28: =N27+M27 -> 85400
D29: C | G29: =G28+F28 -> 425600 | K29: D | N29: =N28+M28 -> 85400
D30: C | G30: =G29+F29 -> 425600 | K30: D | N30: =N29+M29 -> 85400
D31: C | G31: =G30+F30 -> 425600 | K31: D | N31: =N30+M30 -> 85400
D32: C | G32: =G31+F31 -> 425600 | K32: D | N32: =N31+M31 -> 85400
D33: C | G33: =G32+F32 -> 425600 | K33: D | N33: =N32+M32 -> 85400
D34: C | G34: =G33+F33 -> 425600 | K34: D | N34: =N33+M33 -> 85400
A35: †gvU †µwWU t | D35: =G34+F34 -> 425600 | H35: ‡gvU †WweU t | K35: =N34+M34 -> 85400
A36: ‡gvU †WweU t | D36: =K35 -> 85400
A37: eZ©gvb K¨vk t | D37: =D35-D36 -> 340200

Sheet OCT (6)
A1: ‡gmvm© Imgvb wdm& | H1: ‡gmvm© Imgvb wdm&
A2: mvBb‡evW© evRvi grm Avor | H2: mvBb‡evW© evRvi grm Avor
A3: evi t | C3: iweevi | D3: ‡µwWU | F3: ZvwiL t- | G3: 45571 | H3: evi t | J3: iweevi | K3: ‡WwWU | M3: ZvwiL t- | N3: 45571
A4: c~‡e©i K¨vk-Bb-n¨vÛ t | F4: ='OCT (5)'!D37 -> 340200 | G4: **** | J4: ÷vd‡`i bv¯Ív-- | K4: D | M4: 550 | N4: ****
C5: Kwgkb- | D5: C | F5: 7990 | G5: =F4 -> 340200 | J5: eKwkm-- | K5: D | M5: 500 | N5: =M4 -> 550
C6: gmwR`- | D6: C | F6: 70 | G6: =G5+F5 -> 348190 | J6: gUi wdwUsm-- | K6: D | M6: 250 | N6: =N5+M5 -> 1050
C7: mwgwZ- | D7: C | F7: 70 | G7: =G6+F6 -> 348260 | J7: Awdm LiP-- | K7: D | M7: 170 | N7: =N6+M6 -> 1300
C8: gnvwmb Rgv-- | D8: C | F8: 2160 | G8: =G7+F7 -> 348330 | I8: 28bs- | J8: Avt iv¾vK-- | K8: D | L8: 30 bs- | M8: 36620 | N8: =N7+M7 -> 1470
C9: kvwKj Rgv-- | D9: C | F9: 2700 | G9: =G8+F8 -> 350490 | I9: 29bs- | J9: ‡gvZv‡je-- | K9: D | L9: 35 bs- | M9: 6610 | N9: =N8+M8 -> 38090
C10: Avmjvg Rgv-- | D10: C | F10: 15540 | G10: =G9+F9 -> 353190 | I10: 30bs- | J10: ‡gvt jyrdvi-- | K10: D | L10: 31 bs- | M10: 16710 | N10: =N9+M9 -> 44700
C11: ‡ejv‡qZ Rgv-- | D11: C | F11: 10280 | G11: =G10+F10 -> 368730 | I11: 31bs- | J11: iæûj-- | K11: D | L11: 49 bs- | M11: 1120 | N11: =N10+M10 -> 61410
C12: ‡ngv‡qZ Rgv-- | D12: C | F12: 1900 | G12: =G11+F11 -> 379010 | I12: 32bs- | J12: ûgvqyb-- | K12: D | L12: 48 bs- | M12: 3330 | N12: =N11+M11 -> 62530
C13: jyrdvi Rgv-- | D13: C | F13: 5240 | G13: =G12+F12 -> 380910 | I13: 33bs- | J13: kvwgg-- | K13: D | L13: 47 bs- | M13: 3080 | N13: =N12+M12 -> 65860
C14: ‡gvZv‡je Rgv-- | D14: C | F14: 14720 | G14: =G13+F13 -> 386150 | I14: 34bs- | J14: iwdKzj-- | K14: D | L14: 46 bs- | M14: 3080 | N14: =N13+M13 -> 68940
C15: mvjvg Rgv-- | D15: C | F15: 5690 | G15: =G14+F14 -> 400870 | I15: 35bs- | J15: ‡ngv‡qZ-- | K15: D | L15: 45 bs- | M15: 4050 | N15: =N14+M14 -> 72020
C16: ûgvqyb Rgv-- | D16: C | F16: 1390 | G16: =G15+F15 -> 406560 | I16: 36bs- | J16: AvjgwMi-- | K16: D | L16: 44 bs- | M16: 3240 | N16: =N15+M15 -> 76070
D17: C | G17: =G16+F16 -> 407950 | I17: 37bs- | J17: gvgyb-- | K17: D | L17: 43 bs- | M17: 1290 | N17: =N16+M16 -> 79310
D18: C | G18: =G17+F17 -> 407950 | I18: 38bs- | J18: gnvwmb-- | K18: D | L18: 42 bs- | M18: 2360 | N18: =N17+M17 -> 80600
D19: C | G19: =G18+F18 -> 407950 | I19: 39bs- | J19: Gg`v`-- | K19: D | L19: 41 bs- | M19: 2200 | N19: =N18+M18 -> 82960
D20: C | G20: =G19+F19 -> 407950 | I20: 40bs- | J20: iæûj-- | K20: D | L20: 40 bs- | M20: 4440 | N20: =N19+M19 -> 85160
D21: C | G21: =G20+F20 -> 407950 | I21: 41bs- | J21: Avjvwgb-- | K21: D | L21: 39 bs- | M21: 1880 | N21: =N20+M20 -> 89600
D22: C | G22: =G21+F21 -> 407950 | I22: 42bs- | J22: kvwKj-- | K22: D | L22: 38 bs- | M22: 1600 | N22: =N21+M21 -> 91480
D23: C | G23: =G22+F22 -> 407950 | I23: 43bs- | J23: mvjvg-- | K23: D | L23: 37 bs- | M23: 5690 | N23: =N22+M22 -> 93080
D24: C | G24: =G23+F23 -> 407950 | I24: 44bs- | J24: nvwKg-- | K24: D | L24: 36 bs- | M24: 11630 | N24: =N23+M23 -> 98770
D25: C | G25: =G24+F24 -> 407950 | I25: 45bs- | J25: ‡ejv‡qZ-- | K25: D | L25: 34 bs- | M25: 6310 | N25: =N24+M24 -> 110400
D26: C | G26: =G25+F25 -> 407950 | I26: 46bs- | J26: Avmjvg-- | K26: D | L26: 33 bs- | M26: 24620 | N26: =N25+M25 -> 116710
D27: C | G27: =G26+F26 -> 407950 | I27: 47bs- | J27: ‡mv‡nj-- | K27: D | L27: 32 bs- | M27: 7040 | N27: =N26+M26 -> 141330
D28: C | G28: =G27+F27 -> 407950 | K28: D | N28: =N27+M27 -> 148370
D29: C | G29: =G28+F28 -> 407950 | K29: D | N29: =N28+M28 -> 148370
D30: C | G30: =G29+F29 -> 407950 | J30: c~‡e©i LiP-2350 | K30: D | N30: =N29+M29 -> 148370
D31: C | G31: =G30+F30 -> 407950 | J31: AvR‡Ki LiP-1470 | K31: D | N31: =N30+M30 -> 148370
D32: C | G32: =G31+F31 -> 407950 | J32: ‡gvU LiP= 3820 | K32: D | N32: =N31+M31 -> 148370
D33: C | G33: =G32+F32 -> 407950 | K33: D | N33: =N32+M32 -> 148370
D34: C | G34: =G33+F33 -> 407950 | K34: D | N34: =N33+M33 -> 148370
A35: †gvU †µwWU t | D35: =G34+F34 -> 407950 | H35: ‡gvU †WweU t | K35: =N34+M34 -> 148370
A36: ‡gvU †WweU t | D36: =K35 -> 148370
A37: eZ©gvb K¨vk t | D37: =D35-D36 -> 259580

Sheet OCT (7)
A1: ‡gmvm© Imgvb wdm& | H1: ‡gmvm© Imgvb wdm&
A2: mvBb‡evW© evRvi grm Avor | H2: mvBb‡evW© evRvi grm Avor
A3: evi t | C3: †mvgevi | D3: ‡µwWU | F3: ZvwiL t- | G3: 45572 | H3: evi t | J3: †mvgevi | K3: ‡WwWU | M3: ZvwiL t- | N3: 45572
A4: c~‡e©i K¨vk-Bb-n¨vÛ t | F4: ='OCT (6)'!D37 -> 259580 | G4: **** | J4: ÷vd‡`i bv¯Ív-- | K4: D | M4: 600 | N4: ****
C5: Kwgkb- | D5: C | F5: 4470 | G5: =F4 -> 259580 | J5: eKwkm-- | K5: D | M5: 210 | N5: =M4 -> 600
C6: gmwR`- | D6: C | F6: 50 | G6: =G5+F5 -> 264050 | J6: Awdm LiP-- | K6: D | M6: 330 | N6: =N5+M5 -> 810
C7: mwgwZ- | D7: C | F7: 50 | G7: =G6+F6 -> 264100 | J7: ÷vd‡`I cwienb LiP-- | K7: D | M7: 400 | N7: =N6+M6 -> 1140
C8: kvwKj Av`vq- | D8: C | F8: 1600 | G8: =G7+F7 -> 264150 | I8: 48bs- | J8: iv¾vK-- | K8: D | L8: 52 | M8: 14630 | N8: =N7+M7 -> 1540
C9: Avmjvg Av`vq-- | D9: C | F9: 24620 | G9: =G8+F8 -> 265750 | I9: 49bs- | J9: ‡gv¯Í-- | K9: D | L9: 53 | M9: 12140 | N9: =N8+M8 -> 16170
C10: eKzj Av`vq-- | D10: C | F10: 9590 | G10: =G9+F9 -> 290370 | I10: 50bs- | J10: eKzj-- | K10: D | L10: 54 | M10: 15330 | N10: =N9+M9 -> 28310
C11: ‡ngv‡qZ Av`vq-- | D11: C | F11: 4050 | G11: =G10+F10 -> 299960 | I11: 51bs- | J11: ‡gvZv‡je-- | K11: D | L11: 55 | M11: 2500 | N11: =N10+M10 -> 43640
C12: ‡gvt wRKz Av`vq-- | D12: C | F12: 52410 | G12: =G11+F11 -> 304010 | I12: 52bs- | J12: jyrdvi- | K12: D | L12: 56 | M12: 9620 | N12: =N11+M11 -> 46140
C13: RvwKi Av`vq-- | D13: C | F13: 9510 | G13: =G12+F12 -> 356420 | I13: 53bs- | J13: kvwKj-- | K13: D | L13: 57 | M13: 6080 | N13: =N12+M12 -> 55760
C14: ‡gv¯Í Av`vq-- | D14: C | F14: 18920 | G14: =G13+F13 -> 365930 | I14: 54bs- | J14: Avjvwgb-- | K14: D | L14: 58 | M14: 3780 | N14: =N13+M13 -> 61840
C15: iv¾vK Av`vq-- | D15: C | F15: 20510 | G15: =G14+F14 -> 384850 | I15: 55bs- | J15: ‡ngv‡qZ-- | K15: D | L15: 59 | M15: 1260 | N15: =N14+M14 -> 65620
C16: Gg`v` Av`vq-- | D16: C | F16: 2200 | G16: =G15+F15 -> 405360 | I16: 56bs- | J16: ‡ejv‡qZ-- | K16: D | L16: 60 | M16: 3150 | N16: =N15+M15 -> 66880
C17: iwdKzj Av`vq-- | D17: C | F17: 3080 | G17: =G16+F16 -> 407560 | I17: 57bs- | J17: gwZb-- | K17: D | L17: 61 | M17: 1500 | N17: =N16+M16 -> 70030
C18: nvwKg Av`vq-- | D18: C | F18: 11630 | G18: =G17+F17 -> 410640 | I18: 58bs- | J18: gvnveye-- | K18: D | L18: 62 | M18: 6710 | N18: =N17+M17 -> 71530
C19: kvwgg Av`vq-- | D19: C | F19: 3080 | G19: =G18+F18 -> 422270 | I19: 59bs- | J19: mvjvg-- | K19: D | L19: 63 | M19: 4100 | N19: =N18+M18 -> 78240
... C27: Av‡bvqvi Av`vq-- | D27: C | F27: 1100 | G27: =G26+F26 -> 451690 | I27: 67bs- | J27: bM`-- | K27: D | L27: 51 | M27: 300 | N27: =N26+M26 -> 112930
C28: Avjvwgb Av`vq-- | D28: C | F28: 1880 | G28: =G27+F27 -> 452790 | K28: D | N28: =N27+M27 -> 113230
C29: jyrdvi Av`vq-- | D29: C | F29: 14000 | G29: =G28+F28 -> 454670 | K29: D | N29: =N28+M28 -> 113230
C30: bM` weµq-- | D30: C | F30: 8550 | G30: =G29+F29 -> 468670 | K30: D | N30: =N29+M29 -> 113230
C31: bM` weµq-- | D31: C | F31: 300 | G31: =G30+F30 -> 477220 | J31: c~‡e©i LiP-3820 | K31: D | N31: =N30+M30 -> 113230
D32: C | G32: =G31+F31 -> 477520 | J32: AvR‡Ki LiP-1540 | K32: D | N32: =N31+M31 -> 113230
D33: C | G33: =G32+F32 -> 477520 | J33: ‡gvU LiP= 5360 | K33: D | N33: =N32+M32 -> 113230
D34: C | G34: =G33+F33 -> 477520 | K34: D | N34: =N33+M33 -> 113230
A35: †gvU †µwWU t | D35: =G34+F34 -> 477520 | H35: ‡gvU †WweU t | K35: =N34+M34 -> 113230
A36: ‡gvU †WweU t | D36: =K35 -> 113230
A37: eZ©gvb K¨vk t | D37: =D35-D36 -> 364290

Sheet OCT (8)
A1: ‡gmvm© Imgvb wdm& | H1: ‡gmvm© Imgvb wdm&
A2: mvBb‡evW© evRvi grm Avor | H2: mvBb‡evW© evRvi grm Avor
A3: evi t | C3: g½jevi | D3: ‡µwWU | F3: ZvwiL t- | G3: 45573 | H3: evi t | J3: g½jevi | K3: ‡WwWU | M3: ZvwiL t- | N3: 45573
A4: c~‡e©i K¨vk-Bb-n¨vÛ t | F4: ='OCT (7)'!D37 -> 364290 | G4: **** | J4: Awdm LiP-- | K4: D | M4: 550 | N4: ****
C5: Kwgkb- | D5: C | F5: 8140 | G5: =F4 -> 364290 | J5: eKwkm-- | K5: D | M5: 300 | N5: =M4 -> 550
C6: gmwR`- | D6: C | F6: 40 | G6: =G5+F5 -> 372430 | J6: wbjy †gvevBj-- | K6: D | M6: 520 | N6: =N5+M5 -> 850
C7: mwgwZ- | D7: C | F7: 40 | G7: =G6+F6 -> 372470 | J7: gvmyg †gvevBj-- | K7: D | M7: 100 | N7: =N6+M6 -> 1370
C8: bM`- | D8: C | F8: 20830 | G8: =G7+F7 -> 372510 | J8: ÷vd‡`i bv¯Ív-- | K8: D | M8: 500 | N8: =N7+M7 -> 1470
C9: gvnveye Av`vq-- | D9: C | F9: 6710 | G9: =G8+F8 -> 393340 | I9: 68 | J9: ‡gv¯Í-- | K9: D | L9: 70 | M9: 61960 | N9: =N8+M8 -> 1970
C10: ‡mv‡nj Av`vq-- | D10: C | F10: 7040 | G10: =G9+F9 -> 400050 | I10: 69 | J10: ‡gvZv‡je-- | K10: D | L10: 71 | M10: 20190 | N10: =N9+M9 -> 63930
C11: iv¾vK Av`vq-- | D11: C | F11: 30000 | G11: =G10+F10 -> 407090 | I11: 70 | J11: jyrdi-- | K11: D | L11: 72 | M11: 6450 | N11: =N10+M10 -> 84120
C12: ‡ejv‡qZ Av`vq-- | D12: C | F12: 3150 | G12: =G11+F11 -> 437090 | I12: 71 | J12: iv¾vK-- | K12: D | L12: 73 | M12: 11350 | N12: =N11+M11 -> 90570
C13: ‡ngv‡qZ Av`vq-- | D13: C | F13: 1260 | G13: =G12+F12 -> 440240 | I13: 72 | J13: eKzj-- | K13: D | L13: 74 | M13: 30180 | N13: =N12+M12 -> 101920
C14: mvjvg Av`vq-- | D14: C | F14: 4100 | G14: =G13+F13 -> 441500 | I14: 73 | J14: wRKz-- | K14: D | L14: 75 | M14: 3950 | N14: =N13+M13 -> 132100
C15: ‰Zqe Av`vq-- | D15: C | F15: 2730 | G15: =G14+F14 -> 445600 | I15: 74 | J15: ‡gvt ˆZqe-- | K15: D | L15: 76 | M15: 4150 | N15: =N14+M14 -> 136050
C16: nvwKg Av`vq-- | D16: C | F16: 7670 | G16: =G15+F15 -> 448330 | I16: 75 | J16: ‡gvt RvwKi-- | K16: D | L16: 77 | M16: 1610 | N16: =N15+M15 -> 140200
C17: gwZb Av`vq-- | D17: C | F17: 2950 | G17: =G16+F16 -> 456000 | I17: 76 | J17: ‡gvt †ngv‡qZ-- | K17: D | L17: 78 | M17: 2780 | N17: =N16+M16 -> 141810
C18: ‡gvZv‡je Av`vq-- | D18: C | F18: 2500 | G18: =G17+F17 -> 458950 | I18: 77 | J18: ‡gvt gvneye-- | K18: D | L18: 79 | M18: 8310 | N18: =N17+M17 -> 144590
C19: kvgxg Av`vq-- | D19: C | F19: 3150 | G19: =G18+F18 -> 461450 | I19: 78 | J19: ‡gvt nvwKg-- | K19: D | L19: 80 | M19: 3530 | N19: =N18+M18 -> 152900
C20: kwn`yj Av`vq-- | D20: C | F20: 800 | G20: =G19+F19 -> 464600 | I20: 79 | J20: ‡gvt kwn`yj-- | K20: D | L20: 81 | M20: 2810 | N20: =N19+M19 -> 156430
... C24: jyrdi Av`vq-- | D24: C | F24: 12330 | G24: =G23+F23 -> 478800 | I24: 83 | J24: mvjvg-- | K24: D | L24: 85 | M24: 2100 | N24: =N23+M23 -> 168150
D25: C | G25: =G24+F24 -> 491130 | I25: 84 | J25: Gg`v`-- | K25: D | L25: 86 | M25: 1330 | N25: =N24+M24 -> 170250
D26: C | G26: =G25+F25 -> 491130 | I26: 85 | J26: gvgyb-- | K26: D | L26: 87 | M26: 3120 | N26: =N25+M25 -> 171580
D27: C | G27: =G26+F26 -> 491130 | I27: 86 | J27: AvwRRyj-- | K27: D | L27: 88 | M27: 3820 | N27: =N26+M26 -> 174700
D28: C | G28: =G27+F27 -> 491130 | I28: 87 | J28: bM`-- | K28: D | L28: 52 | M28: 20830 | N28: =N27+M27 -> 178520
D29: C | G29: =G28+F28 -> 491130 | I29: 88 | J29: Lvb KvKv-- | K29: D | L29: 53 | M29: 6300 | N29: =N28+M28 -> 199350
D30: C | G30: =G29+F29 -> 491130 | J30: ivZzj †ewk †bqv/K¨vk mU-- | K30: D | M30: 2650 | N30: =N29+M29 -> 205650
D31: C | G31: =G30+F30 -> 491130 | K31: D | N31: =N30+M30 -> 208300
D32: C | G32: =G31+F31 -> 491130 | J32: c~‡e©i LiP-5360 | K32: D | N32: =N31+M31 -> 208300
D33: C | G33: =G32+F32 -> 491130 | J33: AvR‡Ki LiP-4620 | K33: D | N33: =N32+M32 -> 208300
D34: C | G34: =G33+F33 -> 491130 | J34: ‡gvU LiP= 9980 | K34: D | N34: =N33+M33 -> 208300
A35: †gvU †µwWU t | D35: =G34+F34 -> 491130 | H35: ‡gvU †WweU t | K35: =N34+M34 -> 208300
A36: ‡gvU †WweU t | D36: =K35 -> 208300
A37: eZ©gvb K¨vk t | D37: =D35-D36 -> 282830

Sheet OCT (9)
A1: ‡gmvm© Imgvb wdm& | H1: ‡gmvm© Imgvb wdm&
A2: mvBb‡evW© evRvi grm Avor | H2: mvBb‡evW© evRvi grm Avor
A3: evi t | C3: eyaevi | D3: ‡µwWU | F3: ZvwiL t- | G3: 45574 | H3: evi t | J3: eyaevi | K3: ‡WwWU | M3: ZvwiL t- | N3: 45574
A4: c~‡e©i K¨vk-Bb-n¨vÛ t | F4: ='OCT (8)'!D37 -> 282830 | G4: **** | J4: Awdm LiP-- | K4: D | M4: 810 | N4: ****
C5: Kwgkb- | D5: C | F5: 7210 | G5: =F4 -> 282830 | J5: eKwkm-- | K5: D | M5: 240 | N5: =M4 -> 810
C6: gmwR`- | D6: C | F6: 50 | G6: =G5+F5 -> 290040 | J6: ÷vd‡`i bv¯Ív-- | K6: D | M6: 470 | N6: =N5+M5 -> 1050
C7: mwgwZ- | D7: C | F7: 50 | G7: =G6+F6 -> 290090 | I7: 89 | J7: Avt iv¾vK-- | K7: D | L7: 91 | M7: 9720 | N7: =N6+M6 -> 1520
C8: bM`- | D8: C | F8: 14930 | G8: =G7+F7 -> 290140 | I8: 90 | J8: ‡ejv‡qZ-- | K8: D | L8: 95 | M8: 6760 | N8: =N7+M7 -> 11240
C9: bM`- | D9: C | F9: 700 | G9: =G8+F8 -> 305070 | I9: 91 | J9: ‡gvt nvwKg-- | K9: D | L9: 96 | M9: 5170 | N9: =N8+M8 -> 18000
C10: bM`- | D10: C | F10: 3870 | G10: =G9+F9 -> 305770 | I10: 92 | J10: ‡gvt mvjvg-- | K10: D | L10: 97 | M10: 7050 | N10: =N9+M9 -> 23170
C11: bM`- | D11: C | F11: 2110 | G11: =G10+F10 -> 309640 | I11: 93 | J11: ‡gvt Ggvg-- | K11: D | L11: 98 | M11: 4050 | N11: =N10+M10 -> 30220
C12: bM`- | D12: C | F12: 9600 | G12: =G11+F11 -> 311750 | I12: 94 | J12: ‡gvt ˆZqe-- | K12: D | L12: 99 | M12: 5340 | N12: =N11+M11 -> 34270
C13: iv¾vK-- | D13: C | F13: 21250 | G13: =G12+F12 -> 321350 | I13: 95 | J13: ‡gvt ‡gv¯Í-- | K13: D | L13: 92 | M13: 50920 | N13: =N12+M12 -> 39610
C14: ‡gv¯Í-- | D14: C | F14: 12140 | G14: =G13+F13 -> 342600 | I14: 96 | J14: ‡gvt mvnveywÏb-- | K14: D | L14: 100 | M14: 2780 | N14: =N13+M13 -> 90530
C15: eKzj-- | D15: C | F15: 15330 | G15: =G14+F14 -> 354740 | I15: 97 | J15: dviæL-- | K15: D | L15: 58 | M15: 5100 | N15: =N14+M14 -> 93310
C16: Av‡bvqvi-- | D16: C | F16: 4150 | G16: =G15+F15 -> 370070 | I16: 98 | J16: eKzj-- | K16: D | L16: 93 | M16: 29350 | N16: =N15+M15 -> 98410
C17: gvgyb-- | D17: C | F17: 3120 | G17: =G16+F16 -> 374220 | I17: 99 | J17: kvwgg-- | K17: D | L17: 60 | M17: 3310 | N17: =N16+M16 -> 127760
C18: ‡ejv‡qZ-- | D18: C | F18: 5410 | G18: =G17+F17 -> 377340 | I18: 100 | J18: nv‡dR mv‡ne-- | K18: D | L18: 55 | M18: 3000 | N18: =N17+M17 -> 131070
... C23: ‡gvt gvneye-- | D23: C | F23: 8310 | G23: =G22+F22 -> 393120 | I23: 105 | J23: bM`-- | K23: D | L23: 56 | M23: 31210 | N23: =N22+M22 -> 150280
C24: ‡gvt kwn`yj-- | D24: C | F24: 2810 | G24: =G23+F23 -> 401430 | J24: gvmyg †eZb-- | K24: D | M24: 550 | N24: =N23+M23 -> 181490
C25: ‡gvt RvwKi-- | D25: C | F25: 1610 | G25: =G24+F24 -> 404240 | K25: D | N25: =N24+M24 -> 182040
C26: BbQvb-- | D26: C | F26: 1540 | G26: =G25+F25 -> 405850 | K26: D | N26: =N25+M25 -> 182040
C27: AvwRRyj-- | D27: C | F27: 3820 | G27: =G26+F26 -> 407390 | K27: D | N27: =N26+M26 -> 182040
C28: ivZzj †ewk †bqv/K¨vk mU-- | D28: C | F28: 2650 | G28: =G27+F27 -> 411210 | K28: D | N28: =N27+M27 -> 182040
D29: C | G29: =G28+F28 -> 413860 | J29: c~‡e©i LiP-9980 | K29: D | N29: =N28+M28 -> 182040
D30: C | G30: =G29+F29 -> 413860 | J30: AvR‡Ki LiP-2070 | K30: D | N30: =N29+M29 -> 182040
D31: C | G31: =G30+F30 -> 413860 | J31: ‡gvU LiP= 12050 | K31: D | N31: =N30+M30 -> 182040
D32: C | G32: =G31+F31 -> 413860 | J32: (-) ivZzj Rgv-- 2650 | K32: D | N32: =N31+M31 -> 182040
D33: C | G33: =G32+F32 -> 413860 | J33: ‡gvU LiP= 9400 | K33: D | N33: =N32+M32 -> 182040
D34: C | G34: =G33+F33 -> 413860 | K34: D | N34: =N33+M33 -> 182040
A35: †gvU †µwWU t | D35: =G34+F34 -> 413860 | H35: ‡gvU †WweU t | K35: =N34+M34 -> 182040
A36: ‡gvU †WweU t | D36: =K35 -> 182040
A37: eZ©gvb K¨vk t | D37: =D35-D36 -> 231820

Sheet OCT (10)
A1: ‡gmvm© Imgvb wdm& | H1: ‡gmvm© Imgvb wdm&
A2: mvBb‡evW© evRvi grm Avor | H2: mvBb‡evW© evRvi grm Avor
A3: evi t | C3: e„n¯úwZevi | D3: ‡µwWU | F3: ZvwiL t- | G3: 45575 | H3: evi t | J3: e„n¯úwZevi | K3: ‡WwWU | M3: ZvwiL t- | N3: 45575
A4: c~‡e©i K¨vk-Bb-n¨vÛ t | F4: ='OCT (9)'!D37 -> 231820 | G4: **** | J4: Awdm LiP-- | K4: D | M4: 60 | N4: ****
C5: Kwgkb- | D5: C | F5: 9660 | G5: =F4 -> 231820 | J5: eKwkm-- | K5: D | M5: 320 | N5: =M4 -> 60
C6: gmwR`- | D6: C | F6: 50 | G6: =G5+F5 -> 241480 | J6: ÷vd‡`i bv¯Ív-- | K6: D | M6: 500 | N6: =N5+M5 -> 380
C7: mwgwZ- | D7: C | F7: 50 | G7: =G6+F6 -> 241530 | I7: 106 | J7: ‡gvt iv¾vK-- | K7: D | L7: 101 | M7: 2160 | N7: =N6+M6 -> 880
C8: iv¾vK-- | D8: C | F8: 11350 | G8: =G7+F7 -> 241580 | I8: 107 | J8: ‡gvt jytdvi-- | K8: D | L8: 102 | M8: 14190 | N8: =N7+M7 -> 3040
C9: ‡gv¯Í-- | D9: C | F9: 61960 | G9: =G8+F8 -> 252930 | I9: 108 | J9: ‡gvt ‡gv¯Í -- | K9: D | L9: 103 | M9: 31270 | N9: =N8+M8 -> 17230
C10: eKzj-- | D10: C | F10: 30180 | G10: =G9+F9 -> 314890 | I10: 109 | J10: ‡gvt wRKz-- | K10: D | L10: 104 | M10: 15810 | N10: =N9+M9 -> 48500
C11: ‡gvZv‡je-- | D11: C | F11: 6450 | G11: =G10+F10 -> 345070 | I11: 110 | J11: ‡gvt †mvnvM-- | K11: D | L11: 119 | M11: 2480 | N11: =N10+M10 -> 64310
C12: jyrdvi-- | D12: C | F12: 20190 | G12: =G11+F11 -> 351520 | I12: 111 | J12: ‡gvt mvjvg-- | K12: D | L12: 105 | M12: 10080 | N12: =N11+M11 -> 66790
C13: wRKz-- | D13: C | F13: 3950 | G13: =G12+F12 -> 371710 | I13: 112 | J13: ‡gvt †ngv‡qZ-- | K13: D | L13: 106 | M13: 10390 | N13: =N12+M12 -> 76870
C14: Gg`v`-- | D14: C | F14: 1330 | G14: =G13+F13 -> 375660 | I14: 113 | J14: mvnveywÏb-- | K14: D | L14: 107 | M14: 6430 | N14: =N13+M13 -> 87260
C15: ‰Zqe-- | D15: C | F15: 9490 | G15: =G14+F14 -> 376990 | I15: 114 | J15: jvj fvB-- | K15: D | L15: 109 | M15: 2590 | N15: =N14+M14 -> 93690
C16: gnvwmb-- | D16: C | F16: 2360 | G16: =G15+F15 -> 386480 | I16: 115 | J16: kvwgg-- | K16: D | L16: 110 | M16: 7080 | N16: =N15+M15 -> 96280
C17: AvwRRyj-- | D17: C | F17: 6300 | G17: =G16+F16 -> 388840 | I17: 116 | J17: ‡gvnwmb-- | K17: D | L17: 111 | M17: 1070 | N17: =N16+M16 -> 103360
C18: Gbmvb-- | D18: C | F18: 3460 | G18: =G17+F17 -> 395140 | I18: 117 | J18: RvwKi-- | K18: D | L18: 112 | M18: 1690 | N18: =N17+M17 -> 104430
... C25: bM`-- | D25: C | F25: 79620 | G25: =G24+F24 -> 427720 | I25: 124 | J25: kvwKj-- | K25: D | L25: 120 | M25: 13810 | N25: =N24+M24 -> 142230
D26: C | G26: =G25+F25 -> 507340 | I26: 125 | J26: nvwKg-- | K26: D | L26: 121 | M26: 4710 | N26: =N25+M25 -> 156040
D27: C | G27: =G26+F26 -> 507340 | I27: 126 | J27: iæûj Avwgb-- | K27: D | L27: 122 | M27: 2020 | N27: =N26+M26 -> 160750
D28: C | G28: =G27+F27 -> 507340 | I28: 127 | J28: kvnvRvb-- | K28: D | L28: 71 | M28: 100 | N28: =N27+M27 -> 162770
D29: C | G29: =G28+F28 -> 507340 | I29: 128 | J29: bM`-- | K29: D | L29: 72 | M29: 79620 | N29: =N28+M28 -> 162870
D30: C | G30: =G29+F29 -> 507340 | J30: gvmyg †eZb-- | K30: D | M30: 440 | N30: =N29+M29 -> 242490
D31: C | G31: =G30+F30 -> 507340 | K31: D | N31: =N30+M30 -> 242930
D32: C | G32: =G31+F31 -> 507340 | J32: c~‡e©i LiP-9400 | K32: D | N32: =N31+M31 -> 242930
D33: C | G33: =G32+F32 -> 507340 | J33: AvR‡Ki LiP-1320 | K33: D | N33: =N32+M32 -> 242930
C34: 264860 | D34: C | G34: =G33+F33 -> 507340 | J34: ‡gvU LiP= 10720 | K34: D | N34: =N33+M33 -> 242930
A35: †gvU †µwWU t | D35: =G34+F34 -> 507340 | H35: ‡gvU †WweU t | K35: =N34+M34 -> 242930
A36: ‡gvU †WweU t | D36: =K35 -> 242930
A37: eZ©gvb K¨vk t | D37: =D35-D36 -> 264410

Sheet OCT (11)
A1: ‡gmvm© Imgvb wdm& | H1: ‡gmvm© Imgvb wdm&
A2: mvBb‡evW© evRvi grm Avor | H2: mvBb‡evW© evRvi grm Avor
A3: evi t | C3: ïµevi | D3: ‡µwWU | F3: ZvwiL t- | G3: 45576 | H3: evi t | J3: ïµevi | K3: ‡WwWU | M3: ZvwiL t- | N3: 45576
A4: c~‡e©i K¨vk-Bb-n¨vÛ t | F4: ='OCT (10)'!D37 -> 264410 | G4: **** | J4: Awdm LiP-- | K4: D | M4: 130 | N4: ****
C5: Kwgkb- | D5: C | F5: 10490 | G5: =F4 -> 264410 | J5: eKwkm-- | K5: D | M5: 440 | N5: =M4 -> 130
C6: gmwR`- | D6: C | F6: 80 | G6: =G5+F5 -> 274900 | J6: ÷vd‡`i bv¯Ív-- | K6: D | M6: 500 | N6: =N5+M5 -> 570
C7: mwgwZ- | D7: C | F7: 80 | G7: =G6+F6 -> 274980 | I7: 130 | J7: wRKz-- | K7: D | L7: 124 | M7: 70650 | N7: =N6+M6 -> 1070
C8: ‡mvnvM-- | D8: C | F8: 2480 | G8: =G7+F7 -> 275060 | I8: 131 | J8: ‡gvZv‡je-- | K8: D | L8: 128 | M8: 9290 | N8: =N7+M7 -> 71720
C9: jyrdvi-- | D9: C | F9: 15500 | G9: =G8+F8 -> 277540 | I9: 132 | J9: ‡mvnvM-- | K9: D | L9: 138 | M9: 4030 | N9: =N8+M8 -> 81010
C10: gnvwmb-- | D10: C | F10: 1070 | G10: =G9+F9 -> 293040 | I10: 133 | J10: jyrdvi-- | K10: D | L10: 127 | M10: 22060 | N10: =N9+M9 -> 85040
C11: Av‡bvqvi-- | D11: C | F11: 3350 | G11: =G10+F10 -> 294110 | I11: 134 | J11: RvwKi Avor-- | K11: D | L11: 123 | M11: 5920 | N11: =N10+M10 -> 107100
C12: jvj fvB-- | D12: C | F12: 2590 | G12: =G11+F11 -> 297460 | I12: 135 | J12: AvjgwMi-- | K12: D | L12: 144 | M12: 2800 | N12: =N11+M11 -> 113020
C13: ‡ejv‡qZ-- | D13: C | F13: 4490 | G13: =G12+F12 -> 300050 | I13: 136 | J13: Av‡bvqvi-- | K13: D | L13: 132 | M13: 4150 | N13: =N12+M12 -> 115820
C14: kvwKj-- | D14: C | F14: 13810 | G14: =G13+F13 -> 304540 | I14: 137 | J14: ‡ejv‡qZ-- | K14: D | L14: 141 | M14: 21160 | N14: =N13+M13 -> 119970
C15: Avmv`-- | D15: C | F15: 6710 | G15: =G14+F14 -> 318350 | I15: 138 | J15: kvwKj-- | K15: D | L15: 131 | M15: 13830 | N15: =N14+M14 -> 141130
C16: ‡ngv‡qZ-- | D16: C | F16: 10390 | G16: =G15+F15 -> 325060 | I16: 139 | J16: Avmv`-- | K16: D | L16: 139 | M16: 2020 | N16: =N15+M15 -> 154960
C17: Kwig-- | D17: C | F17: 7000 | G17: =G16+F16 -> 335450 | I17: 140 | J17: gwZb-- | K17: D | L17: 126 | M17: 12380 | N17: =N16+M16 -> 156980
C18: kvwgg | D18: C | F18: 7080 | G18: =G17+F17 -> 342450 | I18: 141 | J18: ‡ngv‡qZ-- | K18: D | L18: 140 | M18: 6890 | N18: =N17+M17 -> 169360
... C26: ‡mwjg-- | D26: C | F26: 10000 | G26: =G25+F25 -> 414050 | I26: 149 | J26: mvBdzj-- | K26: D | L26: 143 | M26: 3310 | N26: =N25+M25 -> 212090
D27: C | G27: =G26+F26 -> 424050 | I27: 150 | J27: Rvnvw½i-- | K27: D | L27: 136 | M27: 2430 | N27: =N26+M26 -> 215400
C28: c~‡e©i LiP-10720 | D28: C | G28: =G27+F27 -> 424050 | I28: 151 | J28: Avjg-- | K28: D | L28: 135 | M28: 5950 | N28: =N27+M27 -> 217830
C29: AvR‡Ki LiP-1070 | D29: C | G29: =G28+F28 -> 424050 | I29: 152 | J29: Avjg †gvjøv-- | K29: D | L29: 134 | M29: 3420 | N29: =N28+M28 -> 223780
C30: ‡gvU LiP= 11790 | D30: C | G30: =G29+F29 -> 424050 | I30: 153 | J30: bM`-- | K30: D | L30: 129 | M30: 6340 | N30: =N29+M29 -> 227200
D31: C | G31: =G30+F30 -> 424050 | I31: 154 | J31: bM`-- | K31: D | L31: 142 | M31: 3020 | N31: =N30+M30 -> 233540
C32: AvR‡Ki evKx = 2,26,130/= | D32: C | G32: =G31+F31 -> 424050 | I32: 155 | J32: bM`-- | K32: D | L32: 145 | M32: 3740 | N32: =N31+M31 -> 236560
C33: AvR‡Ki Av`vq = 1,02,710/= | D33: C | G33: =G32+F32 -> 424050 | I33: 156 | J33: bM`-- | K33: D | L33: 101 | M33: 23180 | N33: =N32+M32 -> 240300
D34: C | G34: =G33+F33 -> 424050 | K34: D | N34: =N33+M33 -> 263480
A35: †gvU †µwWU t | D35: =G34+F34 -> 424050 | H35: ‡gvU †WweU t | K35: =N34+M34 -> 263480
A36: ‡gvU †WweU t | D36: =K35 -> 263480
A37: eZ©gvb K¨vk t | D37: =D35-D36 -> 160570

Sheet OCT (12)
A1: ‡gmvm© Imgvb wdm& | H1: ‡gmvm© Imgvb wdm&
A2: mvBb‡evW© evRvi grm Avor | H2: mvBb‡evW© evRvi grm Avor
A3: evi t | C3: kwbevi | D3: ‡µwWU | F3: ZvwiL t- | G3: 45577 | H3: evi t | J3: kwbevi | K3: ‡WwWU | M3: ZvwiL t- | N3: 45577
A4: c~‡e©i K¨vk-Bb-n¨vÛ t | F4: ='OCT (11)'!D37 -> 160570 | G4: **** | J4: Awdm LiP-- | K4: D | M4: 80 | N4: ****
C5: Kwgkb- | D5: C | F5: 7120 | G5: =F4 -> 160570 | J5: eKwkm-- | K5: D | M5: 1970 | N5: =M4 -> 80
C6: gmwR`- | D6: C | F6: 50 | G6: =G5+F5 -> 167690 | J6: ÷vd‡`i bv¯Ív-- | K6: D | M6: 300 | N6: =N5+M5 -> 2050
C7: mwgwZ- | D7: C | F7: 50 | G7: =G6+F6 -> 167740 | J7: Ggv`yj †eZb-- | K7: D | M7: 3000 | N7: =N6+M6 -> 2350
C8: ‡mvnvM Av`vq-- | D8: C | F8: 4030 | G8: =G7+F7 -> 167790 | I8: 157 | J8: wRKz-- | K8: D | L8: 159 | M8: 4700 | N8: =N7+M7 -> 5350
C9: RvwKi Av`vq-- | D9: C | F9: 5920 | G9: =G8+F8 -> 171820 | I9: 158 | J9: ‡gvZv‡je-- | K9: D | L9: 150 | M9: 71470 | N9: =N8+M8 -> 10050
C10: dviæK Av`vq-- | D10: C | F10: 5100 | G10: =G9+F9 -> 177740 | I10: 159 | J10: AvjgwMi-- | K10: D | L10: 157 | M10: 3200 | N10: =N9+M9 -> 81520
C11: wUUz Av`vq-- | D11: C | F11: 3350 | G11: =G10+F10 -> 182840 | I11: 160 | J11: ‡ejv‡qZ-- | K11: D | L11: 149 | M11: 14700 | N11: =N10+M10 -> 84720
C12: mvjvg Av`vq-- | D12: C | F12: 10080 | G12: =G11+F11 -> 186190 | I12: 161 | J12: kvwKj-- | K12: D | L12: 156 | M12: 3060 | N12: =N11+M11 -> 99420
C13: kvwnb Av`vq-- | D13: C | F13: 20080 | G13: =G12+F12 -> 196270 | I13: 162 | J13: kvwnb-- | K13: D | L13: 160 | M13: 3010 | N13: =N12+M12 -> 102480
C14: `yjy Av`vq-- | D14: C | F14: 2810 | G14: =G13+F13 -> 216350 | I14: 163 | J14: nvwKg-- | K14: D | L14: 153 | M14: 3150 | N14: =N13+M13 -> 105490
C15: AvjgwMi KPzqv Av`vq-- | D15: C | F15: 2800 | G15: =G14+F14 -> 219160 | I15: 164 | J15: kvnveywÏb-- | K15: D | L15: 154 | M15: 4950 | N15: =N14+M14 -> 108640
C16: kwn`yj Av`vq-- | D16: C | F16: 3310 | G16: =G15+F15 -> 221960 | I16: 165 | J16: BKivg-- | K16: D | L16: 151 | M16: 13410 | N16: =N15+M15 -> 113590
C17: ‡ejv‡qZ Av`vq-- | D17: C | F17: 21160 | G17: =G16+F16 -> 225270 | I17: 166 | J17: gyiv`-- | K17: D | L17: 152 | M17: 42310 | N17: =N16+M16 -> 127000
C18: ‡ngv‡qZ Av`vq-- | D18: C | F18: 6890 | G18: =G17+F17 -> 246430 | I18: 167 | J18: ev`kv-- | K18: D | L18: 155 | M18: 1930 | N18: =N17+M17 -> 169310
C19: Avmv` Av`vq-- | D19: C | F19: 2020 | G19: =G18+F18 -> 253320 | I19: 168 | J19: wgRvb-- | K19: D | L19: 161 | M19: 6680 | N19: =N18+M18 -> 171240
C20: nvwKg Av`vq-- | D20: C | F20: 6830 | G20: =G19+F19 -> 255340 | I20: 169 | J20: bM`-- | K20: D | L20: 121 | M20: 5650 | N20: =N19+M19 -> 177920
C21: Rvnvw½i Av`vq-- | D21: C | F21: 2430 | G21: =G20+F20 -> 262170 | K21: D | N21: =N20+M20 -> 183570
C22: Avjg evRvi Av`vq-- | D22: C | F22: 5950 | G22: =G21+F21 -> 264600 | K22: D | N22: =N21+M21 -> 183570
C23: Avjg ‡gvjøv Av`vq-- | D23: C | F23: 3420 | G23: =G22+F22 -> 270550 | K23: D | N23: =N22+M22 -> 183570
C24: Avjvwgb Av`vq-- | D24: C | F24: 560 | G24: =G23+F23 -> 273970 | K24: D | N24: =N23+M23 -> 183570
C25: kvwKj Av`vq-- | D25: C | F25: 13830 | G25: =G24+F24 -> 274530 | K25: D | N25: =N24+M24 -> 183570
C26: bM` weµq-- | D26: C | F26: 5650 | G26: =G25+F25 -> 288360 | K26: D | N26: =N25+M25 -> 183570
D27: C | G27: =G26+F26 -> 294010 | K27: D | N27: =N26+M26 -> 183570
D28: C | G28: =G27+F27 -> 294010 | K28: D | N28: =N27+M27 -> 183570
D29: C | G29: =G28+F28 -> 294010 | J29: c~‡e©i LiP-11790 | K29: D | N29: =N28+M28 -> 183570
D30: C | G30: =G29+F29 -> 294010 | J30: AvR‡Ki LiP-5350 | K30: D | N30: =N29+M29 -> 183570
C31: AvR‡Ki evKx = 1,72,570/= | D31: C | G31: =G30+F30 -> 294010 | J31: ‡gvU LiP= 17140 | K31: D | N31: =N30+M30 -> 183570
C32: AvR‡Ki Av`vq = 1,20,570/= | D32: C | G32: =G31+F31 -> 294010 | K32: D | N32: =N31+M31 -> 183570
D33: C | G33: =G32+F32 -> 294010 | K33: D | N33: =N32+M32 -> 183570
D34: C | G34: =G33+F33 -> 294010 | K34: D | N34: =N33+M33 -> 183570
A35: †gvU †µwWU t | D35: =G34+F34 -> 294010 | H35: ‡gvU †WweU t | K35: =N34+M34 -> 183570
A36: ‡gvU †WweU t | D36: =K35 -> 183570
A37: eZ©gvb K¨vk t | D37: =D35-D36 -> 110440

Sheet OCT (13)
A1: ‡gmvm© Imgvb wdm& | H1: ‡gmvm© Imgvb wdm&
A2: mvBb‡evW© evRvi grm Avor | H2: mvBb‡evW© evRvi grm Avor
A3: evi t | C3: iweevi | D3: ‡µwWU | F3: ZvwiL t- | G3: 45578 | H3: evi t | J3: iweevi | K3: ‡WwWU | M3: ZvwiL t- | N3: 45578
A4: c~‡e©i K¨vk-Bb-n¨vÛ t | F4: ='OCT (12)'!D37 -> 110440 | G4: **** | J4: Awdm LiP-- | K4: D | M4: 320 | N4: ****
C5: Kwgkb- | D5: C | F5: 14880 | G5: =F4 -> 110440 | J5: ÷vd‡`i bv¯Ív-- | K5: D | M5: 300 | N5: =M4 -> 320
C6: gmwR`- | D6: C | F6: 120 | G6: =G5+F5 -> 125320 | J6: eKwkm-- | K6: D | L6: 260 | M6: 1210 | N6: =N5+M5 -> 620
C7: mwgwZ- | D7: C | F7: 120 | G7: =G6+F6 -> 125440 | I7: 170 | J7: iv¾vK-- | K7: D | L7: 163 | M7: 10730 | N7: =N6+M6 -> 1830
C8: g~jab †`qv-- | D8: C | F8: 200000 | G8: =G7+F7 -> 125560 | I8: 171 | J8: eKzj-- | K8: D | L8: 191 | M8: 1130 | N8: =N7+M7 -> 12560
C9: jyrdvi Av`vq-- | D9: C | F9: 23850 | G9: =G8+F8 -> 325560 | I9: 172 | J9: wRKz-- | K9: D | L9: 185 | M9: 45370 | N9: =N8+M8 -> 13690
C10: ‡gvZv‡je-- | D10: C | F10: 9000 | G10: =G9+F9 -> 349410 | I10: 173 | J10: jyrdvi-- | K10: D | L10: 182 | M10: 34850 | N10: =N9+M9 -> 59060
C11: Lvb KvKv-- | D11: C | F11: 6300 | G11: =G10+F10 -> 358410 | I11: 174 | J11: gyiv` (XvKv)-- | K11: D | L11: 169 | M11: 67200 | N11: =N10+M10 -> 93910
C12: nv‡dR mv‡ne-- | D12: C | F12: 3000 | G12: =G11+F11 -> 364710 | I12: 175 | J12: Rvnvw½i-- | K12: D | L12: 192 | M12: 4100 | N12: =N11+M11 -> 161110
C13: kvnRvnvb-- | D13: C | F13: 100 | G13: =G12+F12 -> 367710 | I13: 176 | J13: evnv`yi-- | K13: D | L13: 187 | M13: 5360 | N13: =N12+M12 -> 165210
C14: gwZb-- | D14: C | F14: 12380 | G14: =G13+F13 -> 367810 | I14: 177 | J14: Gbmvb-- | K14: D | L14: 186 | M14: 5780 | N14: =N13+M13 -> 170570
C15: kwn`yj-- | D15: C | F15: 650 | G15: =G14+F14 -> 380190 | I15: 178 | J15: wgRvb-- | K15: D | L15: 184 | M15: 4960 | N15: =N14+M14 -> 176350
C16: Av‡bvqvi-- | D16: C | F16: 4150 | G16: =G15+F15 -> 380840 | I16: 179 | J16: iv‡mj-- | K16: D | L16: 183 | M16: 3720 | N16: =N15+M15 -> 181310
C17: Kwig-- | D17: C | F17: 3890 | G17: =G16+F16 -> 384990 | I17: 180 | J17: iæûj-- | K17: D | L17: 179 | M17: 4560 | N17: =N16+M16 -> 185030
C18: GKivg-- | D18: C | F18: 13410 | G18: =G17+F17 -> 388880 | I18: 181 | J18: BKevj-- | K18: D | L18: 181 | M18: 5470 | N18: =N17+M17 -> 189590
... C25: bM` weµq-- | D25: C | F25: 27500 | G25: =G24+F24 -> 437840 | I25: 188 | J25: imyj-- | K25: D | L25: 172 | M25: 3110 | N25: =N24+M24 -> 252870
D26: C | G26: =G25+F25 -> 465340 | I26: 189 | J26: Bgvg-- | K26: D | L26: 170 | M26: 6850 | N26: =N25+M25 -> 255980
C27: AvR‡Ki evKx = 3,45,080/= | D27: C | G27: =G26+F26 -> 465340 | I27: 190 | J27: gvneye-- | K27: D | L27: 168 | M27: 17860 | N27: =N26+M26 -> 262830
C28: AvR‡Ki Av`vq = 1,12,280/= | D28: C | G28: =G27+F27 -> 465340 | I28: 191 | J28: wUUz-- | K28: D | L28: 167 | M28: 7530 | N28: =N27+M27 -> 280690
D29: C | G29: =G28+F28 -> 465340 | I29: 192 | J29: gwZb-- | K29: D | L29: 189171 | M29: 30280 | N29: =N28+M28 -> 288220
D30: C | G30: =G29+F29 -> 465340 | I30: 193 | J30: m`v-- | K30: D | L30: 190 | M30: 210 | N30: =N29+M29 -> 318500
C31: c~‡e©i LiP-17140 | D31: C | G31: =G30+F30 -> 465340 | I31: 194 | J31: kvwKj-- | K31: D | L31: 164 | M31: 7590 | N31: =N30+M30 -> 318710
C32: AvR‡Ki LiP-1830 | D32: C | G32: =G31+F31 -> 465340 | I32: 195 | J32: Av‡bvqvi-- | K32: D | L32: 165 | M32: 20610 | N32: =N31+M31 -> 326300
C33: ‡gvU LiP= 18970 | D33: C | G33: =G32+F32 -> 465340 | I33: 196 | J33: bM` weµq-- | K33: D | L33: 161 | M33: 27500 | N33: =N32+M32 -> 346910
D34: C | G34: =G33+F33 -> 465340 | K34: D | N34: =N33+M33 -> 374410
A35: †gvU †µwWU t | D35: =G34+F34 -> 465340 | H35: ‡gvU †WweU t | K35: =N34+M34 -> 374410
A36: ‡gvU †WweU t | D36: =K35 -> 374410
A37: eZ©gvb K¨vk t | D37: =D35-D36 -> 90930

Sheet OCT (14)
A1: ‡gmvm© Imgvb wdm& | H1: ‡gmvm© Imgvb wdm&
A2: mvBb‡evW© evRvi grm Avor | H2: mvBb‡evW© evRvi grm Avor
A3: evi t | C3: ‡mvgevi | D3: ‡µwWU | F3: ZvwiL t- | G3: 45579 | H3: evi t | J3: ‡mvgevi | K3: ‡WwWU | M3: ZvwiL t- | N3: 45579
A4: c~‡e©i K¨vk-Bb-n¨vÛ t | F4: ='OCT (13)'!D37 -> 90930 | G4: **** | J4: Awdm LiP-- | K4: D | M4: 200 | N4: ****
C5: Kwgkb- | D5: C | F5: 19340 | G5: =F4 -> 90930 | J5: ÷vd‡`i bv¯Ív-- | K5: D | M5: 250 | N5: =M4 -> 200
C6: gmwR`- | D6: C | F6: 160 | G6: =G5+F5 -> 110270 | J6: eKwkm-- | K6: D | L6: 200 | M6: 1450 | N6: =N5+M5 -> 450
C7: mwgwZ- | D7: C | F7: 160 | G7: =G6+F6 -> 110430 | I7: 197 | J7: iv¾vK-- | K7: D | L7: 200 | M7: 30740 | N7: =N6+M6 -> 1900
C8: g~jab-- | D8: C | F8: 400000 | G8: =G7+F7 -> 110590 | I8: 198 | J8: ‡gv¯Í XvKv-- | K8: D | L8: 202 | M8: 34360 | N8: =N7+M7 -> 32640
C9: jyrdvi-- | D9: C | F9: 25000 | G9: =G8+F8 -> 510590 | I9: 199 | J9: eKzj XvKv-- | K9: D | L9: 195 | M9: 70050 | N9: =N8+M8 -> 67000
C10: ‡mvnvM-- | D10: C | F10: 4210 | G10: =G9+F9 -> 535590 | I10: 200 | J10: wRKz fvB-- | K10: D | L10: 197 | M10: 14710 | N10: =N9+M9 -> 137050
C11: AvjgwMi-- | D11: C | F11: 3200 | G11: =G10+F10 -> 539800 | I11: 201 | J11: ‡gvZv‡je-- | K11: D | L11: 194 | M11: 27890 | N11: =N10+M10 -> 151760
C12: kvwKj-- | D12: C | F12: 7590 | G12: =G11+F11 -> 543000 | I12: 202 | J12: ‡mvnvM-- | K12: D | L12: 200 | M12: 4970 | N12: =N11+M11 -> 179650
C13: ‡ejv‡qZ-- | D13: C | F13: 10280 | G13: =G12+F12 -> 550590 | I13: 203 | J13: jyrdi-- | K13: D | L13: 196 | M13: 22310 | N13: =N12+M12 -> 184620
C14: gvneye-- | D14: C | F14: 17860 | G14: =G13+F13 -> 560870 | I14: 204 | J14: gyiv` -- | K14: D | L14: 210 | M14: 11600 | N14: =N13+M13 -> 206930
C15: Ggvg-- | D15: C | F15: 6850 | G15: =G14+F14 -> 578730 | I15: 205 | J15: ‡ejv‡qZ-- | K15: D | L15: 204 | M15: 9510 | N15: =N14+M14 -> 218530
C16: imyj-- | D16: C | F16: 3110 | G16: =G15+F15 -> 585580 | I16: 206 | J16: gwZb-- | K16: D | L16: 198 | M16: 25050 | N16: =N15+M15 -> 228040
C17: kwn`yj-- | D17: C | F17: 6070 | G17: =G16+F16 -> 588690 | I17: 207 | J17: ‡ngv‡qZ-- | K17: D | L17: 207 | M17: 8660 | N17: =N16+M16 -> 253090
C18: iæûj-- | D18: C | F18: 4560 | G18: =G17+F17 -> 594760 | I18: 208 | J18: Bgvg-- | K18: D | L18: 215 | M18: 7690 | N18: =N17+M17 -> 261750
... C23: bM`-- | D23: C | F23: 33700 | G23: =G22+F22 -> 619250 | I23: 213 | J23: AvwRRyj-- | K23: D | L23: 199 | M23: 80550 | N23: =N22+M22 -> 282540
D24: C | G24: =G23+F23 -> 652950 | I24: 214 | J24: GKivg-- | K24: D | L24: 217 | M24: 4600 | N24: =N23+M23 -> 363090
D25: C | G25: =G24+F24 -> 652950 | I25: 215 | J25: Rqbvj-- | K25: D | L25: 205 | M25: 10920 | N25: =N24+M24 -> 367690
D26: C | G26: =G25+F25 -> 652950 | I26: 216 | J26: kwn`-- | K26: D | L26: 206 | M26: 6330 | N26: =N25+M25 -> 378610
D27: C | G27: =G26+F26 -> 652950 | I27: 217 | J27: BwjqvQ-- | K27: D | L27: 211 | M27: 5930 | N27: =N26+M26 -> 384940
C28: AvR‡Ki evKx = 4,50,390/= | D28: C | G28: =G27+F27 -> 652950 | I28: 218 | J28: my‡`e-- | K28: D | L28: 213 | M28: 550 | N28: =N27+M27 -> 390870
C29: AvR‡Ki Av`vq = 1,08,660/= | D29: C | G29: =G28+F28 -> 652950 | I29: 219 | J29: RvwKi-- | K29: D | L29: 214 | M29: 720 | N29: =N28+M28 -> 391420
D30: C | G30: =G29+F29 -> 652950 | I30: 220 | J30: w`b eÜz-- | K30: D | L30: 216 | M30: 39780 | N30: =N29+M29 -> 392140
D31: C | G31: =G30+F30 -> 652950 | I31: 221 | J31: ‰Zqe fvB-- | K31: D | L31: 218 | M31: 2970 | N31: =N30+M30 -> 431920
C32: c~‡e©i LiP-18970 | D32: C | G32: =G31+F31 -> 652950 | I32: 222 | J32: gvneye wi‡mvU©-- | K32: D | L32: 219 | M32: 12160 | N32: =N31+M31 -> 434890
C33: AvR‡Ki LiP-1900 | D33: C | G33: =G32+F32 -> 652950 | I33: 223 | J33: BKevj-- | K33: D | L33: 220 | M33: 2500 | N33: =N32+M32 -> 447050
C34: ‡gvU LiP= 20870 | D34: C | G34: =G33+F33 -> 652950 | I34: 224 | J34: ‡gvt gvgyb-- | K34: D | L34: 222 | M34: 2740 | N34: =N33+M33 -> 449550
D35: C | G35: =G34+F34 -> 652950 | I35: 225+226 | J35: bM`-- | K35: D | L35: 193201 | M35: 33700 | N35: =N34+M34 -> 452290
D36: C | G36: =G35+F35 -> 652950 | J36: ‡mwj‡gi cvIbv UvKv cwi‡kva-- | K36: D | M36: 10000 | N36: =N35+M35 -> 485990
D37: C | G37: =G36+F36 -> 652950 | J37: wbjy avi-- | K37: D | M37: 16400 | N37: =N36+M36 -> 495990
A38: †gvU †µwWU t | D38: =G37+F37 -> 652950 | H38: ‡gvU †WweU t | K38: =N37+M37 -> 512390
A39: ‡gvU †WweU t | D39: =K38 -> 512390
A40: eZ©gvb K¨vk t | D40: =D38-D39 -> 140560

Sheet OCT (15)
A1: ‡gmvm© Imgvb wdm& | H1: ‡gmvm© Imgvb wdm&
A2: mvBb‡evW© evRvi grm Avor | H2: mvBb‡evW© evRvi grm Avor
A3: evi t | C3: g½jevi | D3: ‡µwWU | F3: ZvwiL t- | G3: 45580 | H3: evi t | J3: g½jevi | K3: ‡WwWU | M3: ZvwiL t- | N3: 45580
A4: c~‡e©i K¨vk-Bb-n¨vÛ t | F4: ='OCT (14)'!D40 -> 140560 | G4: **** | J4: Awdm LiP-- | K4: D | M4: 1000 | N4: ****
C5: Kwgkb-- | D5: C | F5: 11970 | G5: =F4 -> 140560 | J5: eKwkm-- | K5: D | M5: 690 | N5: =M4 -> 1000
C6: gmwR`- | D6: C | F6: 130 | G6: =G5+F5 -> 152530 | J6: ÷vd‡`i bv¯Ív-- | K6: D | M6: 410 | N6: =N5+M5 -> 1690
C7: mwgwZ- | D7: C | F7: 130 | G7: =G6+F6 -> 152660 | I7: 227 | J7: iv¾vK-- | K7: D | M7: 6680 | N7: =N6+M6 -> 2100
C8: g~jab †`qv-- | D8: C | F8: 50000 | G8: =G7+F7 -> 152790 | I8: 228 | J8: ‡gv¯Í-- | K8: D | M8: 10420 | N8: =N7+M7 -> 8780
C9: wbjy Rgv-- | D9: C | F9: 16400 | G9: =G8+F8 -> 202790 | I9: 229 | J9: eKzj-- | K9: D | M9: 14050 | N9: =N8+M8 -> 19200
C10: iv¾vK-- | D10: C | F10: 22610 | G10: =G9+F9 -> 219190 | I10: 230 | J10: wRKz-- | K10: D | M10: 39410 | N10: =N9+M9 -> 33250
C11: ‡gv¯Í-- | D11: C | F11: 60000 | G11: =G10+F10 -> 241800 | I11: 231 | J11: ‡gvZv‡je-- | K11: D | M11: 16500 | N11: =N10+M10 -> 72660
C12: eKzj-- | D12: C | F12: 29350 | G12: =G11+F11 -> 301800 | I12: 232 | J12: jyrdvi-- | K12: D | M12: 22280 | N12: =N11+M11 -> 89160
C13: gyiv`-- | D13: C | F13: 80000 | G13: =G12+F12 -> 331150 | I13: 233 | J13: fvB fvB wdm-- | K13: D | M13: 13150 | N13: =N12+M12 -> 111440
C14: ev`kv-- | D14: C | F14: 1930 | G14: =G13+F13 -> 411150 | I14: 234 | J14: Av‡bvqvi-- | K14: D | M14: 4830 | N14: =N13+M13 -> 124590
C15: Av‡bvqvi-- | D15: C | F15: 20610 | G15: =G14+F14 -> 413080 | I15: 235 | J15: Rvnvw½i-- | K15: D | M15: 700 | N15: =N14+M14 -> 129420
C16: gwZb-- | D16: C | F16: 55330 | G16: =G15+F15 -> 433690 | I16: 236 | J16: ‡ejv‡qZ-- | K16: D | M16: 3320 | N16: =N15+M15 -> 130120
C17: Kwig-- | D17: C | F17: 3150 | G17: =G16+F16 -> 489020 | I17: 237 | J17: gwZb-- | K17: D | M17: 55250 | N17: =N16+M16 -> 133440
C18: AvwRRyj-- | D18: C | F18: 30000 | G18: =G17+F17 -> 492170 | I18: 238 | J18: ‡ngv‡qZ-- | K18: D | M18: 2970 | N18: =N17+M17 -> 188690
... C33: BwjqvQ-- | D33: C | F33: 5930 | G33: =G32+F32 -> 609240 | I33: 253 | J33: bM`-- | K33: D | M33: 38480 | N33: =N32+M32 -> 263880
C34: bM` weµq-- | D34: C | F34: 38480 | G34: =G33+F33 -> 615170 | J34: nvweeyjøvn-- | K34: D | M34: 50000 | N34: =N33+M33 -> 302360
G35: =G34+F34 -> 653650 | N35: =N34+M34 -> 352360
G36: =G35+F35 -> 653650 | N36: =N35+M35 -> 352360
C37: AvR‡Ki evKx = 2,61,780/= | G37: =G36+F36 -> 653650 | J37: c~‡e©i LiP-20870 | N37: =N36+M36 -> 352360
C38: AvR‡Ki Av`vq = 3,95,980/= | G38: =G37+F37 -> 653650 | J38: AvR‡Ki LiP-2100 | N38: =N37+M37 -> 352360
G39: =G38+F38 -> 653650 | J39: ‡gvU LiP= 22970 | N39: =N38+M38 -> 352360
A40: †gvU †µwWU t | D40: =G39+F39 -> 653650 | H40: ‡gvU †WweU t | K40: =N39+M39 -> 352360
A41: ‡gvU †WweU t | D41: =K40 -> 352360
A42: eZ©gvb K¨vk t | D42: =D40-D41 -> 301290

Sheet OCT (16)
A1: ‡gmvm© Imgvb wdm& | H1: ‡gmvm© Imgvb wdm&
A2: mvBb‡evW© evRvi grm Avor | H2: mvBb‡evW© evRvi grm Avor
A3: evi t | C3: eyaevi | D3: ‡µwWU | F3: ZvwiL t- | G3: 46311 | H3: evi t | J3: eyaevi | K3: ‡WwWU | M3: ZvwiL t- | N3: 46311
A4: c~‡e©i K¨vk-Bb-n¨vÛ t | F4: ='OCT (15)'!D42 -> 301290 | G4: **** | J4: Awdm LiP-- | K4: D | M4: 1110 | N4: ****
C5: Kwgkb-- | D5: C | F5: 9360 | G5: =F4 -> 301290 | J5: eKwkm-- | K5: D | L5: 120 | M5: 720 | N5: =M4 -> 1110
C6: gmwR`- | D6: C | F6: 110 | G6: =G5+F5 -> 310650 | J6: ÷vd‡`i bv¯Ív-- | K6: D | M6: 350 | N6: =N5+M5 -> 1830
C7: mwgwZ- | D7: C | F7: 110 | G7: =G6+F6 -> 310760 | J7: m`v †eZb- | K7: D | M7: 1000 | N7: =N6+M6 -> 2180
C8: iv¾vK-- | D8: C | F8: 30740 | G8: =G7+F7 -> 310870 | I8: 254 | J8: iv¾vK-- | K8: D | L8: 269 | M8: 7350 | N8: =N7+M7 -> 3180
C9: ‡gv¯Í-- | D9: C | F9: 50000 | G9: =G8+F8 -> 341610 | I9: 255 | J9: ‡gv¯Í-- | K9: D | L9: 249 | M9: 26700 | N9: =N8+M8 -> 10530
C10: eKzj-- | D10: C | F10: 70050 | G10: =G9+F9 -> 391610 | I10: 256 | J10: wRKz-- | K10: D | L10: 258 | M10: 21540 | N10: =N9+M9 -> 37230
C11: wRKz-- | D11: C | F11: 101240 | G11: =G10+F10 -> 461660 | I11: 257 | J11: ‡gvZv‡je-- | K11: D | L11: 259 | M11: 35060 | N11: =N10+M10 -> 58770
C12: ‡gvZv‡je-- | D12: C | F12: 99650 | G12: =G11+F11 -> 562900 | I12: 258 | J12: jyrdvi-- | K12: D | L12: 262 | M12: 3980 | N12: =N11+M11 -> 93830
C13: gyiv`-- | D13: C | F13: 35000 | G13: =G12+F12 -> 662550 | I13: 259 | J13: gyiv`-- | K13: D | L13: 261 | M13: 8640 | N13: =N12+M12 -> 97810
C14: AvwRRyj-- | D14: C | F14: 75000 | G14: =G13+F13 -> 697550 | I14: 260 | J14: evnv`yi-- | K14: D | L14: 266 | M14: 6320 | N14: =N13+M13 -> 106450
C15: Øxb eÜz-- | D15: C | F15: 39500 | G15: =G14+F14 -> 772550 | I15: 261 | J15: Av‡bvqvi-- | K15: D | L15: 252 | M15: 11530 | N15: =N14+M14 -> 112770
C16: nvB-- | D16: C | F16: 2010 | G16: =G15+F15 -> 812050 | I16: 262 | J16: Rvnvw½i-- | K16: D | L16: 273 | M16: 5000 | N16: =N15+M15 -> 124300
C17: Rqbvj-- | D17: C | F17: 10920 | G17: =G16+F16 -> 814060 | I17: 263 | J17: Rqbvj-- | K17: D | L17: 275 | M17: 1880 | N17: =N16+M16 -> 129300
C18: kwn`yj-- | D18: C | F18: 6330 | G18: =G17+F17 -> 824980 | I18: 264 | J18: ‡ejv‡qZ-- | K18: D | L18: 268 | M18: 2700 | N18: =N17+M17 -> 131180
C19: my‡`e-- | D19: C | F19: 550 | G19: =G18+F18 -> 831310 | I19: 265 | J19: gwZb-- | K19: D | L19: 263 | M19: 11090 | N19: =N18+M18 -> 133880
... C36: bM`-- | D36: C | F36: 28530 | G36: =G35+F35 -> 889840 | I36: 282 | J36: iv¾vK evRvi-- | K36: D | L36: 254 | M36: 2320 | N36: =N35+M35 -> 205900
D37: C | G37: =G36+F36 -> 918370 | I37: 283 | J37: Lvb KvKv-- | K37: D | L37: 279 | M37: 720 | N37: =N36+M36 -> 208220
D38: C | G38: =G37+F37 -> 918370 | I38: 284 | J38: bM`-- | K38: D | L38: 203 | M38: 28530 | N38: =N37+M37 -> 208940
C39: AvR‡Ki evKx = 2,05,760/= | D39: C | G39: =G38+F38 -> 918370 | K39: D | N39: =N38+M38 -> 237470
C40: AvR‡Ki Av`vq = 5,78,970/= | G40: =G39+F39 -> 918370 | J40: c~‡e©i LiP-22970 | N40: =N39+M39 -> 237470
G41: =G40+F40 -> 918370 | J41: AvR‡Ki LiP-3180 | N41: =N40+M40 -> 237470
D42: C | G42: =G41+F41 -> 918370 | J42: ‡gvU LiP= 26150 | N42: =N41+M41 -> 237470
A43: †gvU †µwWU t | D43: =G42+F42 -> 918370 | H43: ‡gvU †WweU t | K43: =N42+M42 -> 237470
A44: ‡gvU †WweU t | D44: =K43 -> 237470
A45: eZ©gvb K¨vk t | D45: =D43-D44 -> 680900

Sheet OCT (17)
A1: ‡gmvm© Imgvb wdm& | H1: ‡gmvm© Imgvb wdm&
A2: mvBb‡evW© evRvi grm Avor | H2: mvBb‡evW© evRvi grm Avor
A3: evi t | C3: e„n¯úwZevi | D3: ‡µwWU | F3: ZvwiL t- | G3: 45582 | H3: evi t | J3: e„n¯úwZevi | K3: ‡WwWU | M3: ZvwiL t- | N3: 45582
A4: c~‡e©i K¨vk-Bb-n¨vÛ t | F4: ='OCT (16)'!D45 -> 680900 | G4: **** | J4: Awdm LiP-- | K4: D | M4: 330 | N4: ****
C5: Kwgkb-- | D5: C | F5: 12390 | G5: =F4 -> 680900 | J5: eKwkm-- | K5: D | M5: 1250 | N5: =M4 -> 330
C6: gmwR`- | D6: C | F6: 130 | G6: =G5+F5 -> 693290 | J6: ÷vd‡`i bv¯Ív-- | K6: D | M6: 300 | N6: =N5+M5 -> 1580
C7: mwgwZ- | D7: C | F7: 130 | G7: =G6+F6 -> 693420 | J7: ms¯’vcb e¨q-- | K7: D | M7: 2000 | N7: =N6+M6 -> 1880
C8: iv¾vK-- | D8: C | F8: 6680 | G8: =G7+F7 -> 693550 | I8: 285 | J8: iv¾vK-- | K8: D | L8: 298 | M8: 2650 | N8: =N7+M7 -> 3880
C9: ‡gv¯Í-- | D9: C | F9: 10420 | G9: =G8+F8 -> 700230 | I9: 286 | J9: ‡gv¯Í-- | K9: D | L9: 283 | M9: 29990 | N9: =N8+M8 -> 6530
C10: eKzj-- | D10: C | F10: 14050 | G10: =G9+F9 -> 710650 | I10: 287 | J10: eKzj-- | K10: D | L10: 284 | M10: 29610 | N10: =N9+M9 -> 36520
C11: wRKz-- | D11: C | F11: 50000 | G11: =G10+F10 -> 724700 | I11: 288 | J11: wRKz-- | K11: D | L11: 310 | M11: 15210 | N11: =N10+M10 -> 66130
C12: jyrdvi-- | D12: C | F12: 24000 | G12: =G11+F11 -> 774700 | I12: 289 | J12: ‡gvZv‡je-- | K12: D | L12: 293 | M12: 30540 | N12: =N11+M11 -> 81340
C13: ‡gvZv‡je-- | D13: C | F13: 50000 | G13: =G12+F12 -> 798700 | I13: 290 | J13: jyrdvi-- | K13: D | L13: 295 | M13: 26270 | N13: =N12+M12 -> 111880
C14: AvwRRyj-- | D14: C | F14: 25000 | G14: =G13+F13 -> 848700 | I14: 291 | J14: ‡mvnvM-- | K14: D | L14: 281 | M14: 5500 | N14: =N13+M13 -> 138150
C15: my‡`e-- | D15: C | F15: 8270 | G15: =G14+F14 -> 873700 | I15: 292 | J15: gyiv`-- | K15: D | L15: 305 | M15: 22870 | N15: =N14+M14 -> 143650
C16: fvB fvB wdm-- | D16: C | F16: 14280 | G16: =G15+F15 -> 881970 | I16: 293 | J16: AvwRRyj-- | K16: D | L16: 282 | M16: 40090 | N16: =N15+M15 -> 166520
C17: gwZb-- | D17: C | F17: 55250 | G17: =G16+F16 -> 896250 | I17: 294 | J17: Rvnvw½i-- | K17: D | L17: 301 | M17: 2700 | N17: =N16+M16 -> 206610
C18: gnvwmb-- | D18: C | F18: 1340 | G18: =G17+F17 -> 951500 | I18: 295 | J18: gwZb-- | K18: D | L18: 296 | M18: 18900 | N18: =N17+M17 -> 209310
C19: iwk`-- | D19: C | F19: 430 | G19: =G18+F18 -> 952840 | I19: 296 | J19: Gbmvb-- | K19: D | L19: 297 | M19: 1470 | N19: =N18+M18 -> 228210
... C34: bM`-- | D34: C | F34: 29440 | G34: =G33+F33 -> 1008170 | I34: 311 | J34: bM`-- | K34: D | L34: 251 | M34: 29440 | N34: =N33+M33 -> 284820
G35: =G34+F34 -> 1037610 | J35: g~jab †diZ-- | K35: D | M35: 400000 | N35: =N34+M34 -> 314260
G36: =G35+F35 -> 1037610 | J36: wbjy avi-- | K36: D | M36: 4690 | N36: =N35+M35 -> 714260
C37: AvR‡Ki evKx = 2,80,940/= | G37: =G36+F36 -> 1037610 | K37: D | N37: =N36+M36 -> 718950
C38: AvR‡Ki Av`vq = 3,14,620/= | G38: =G37+F37 -> 1037610 | K38: D | N38: =N37+M37 -> 718950
G39: =G38+F38 -> 1037610 | J39: c~‡e©i LiP-26150/= | K39: D | N39: =N38+M38 -> 718950
G40: =G39+F39 -> 1037610 | J40: AvR‡Ki LiP-3880/= | K40: D | N40: =N39+M39 -> 718950
G41: =G40+F40 -> 1037610 | J41: ‡gvU LiP= 30030/= | K41: D | N41: =N40+M40 -> 718950
A42: †gvU †µwWU t | D42: =G41+F41 -> 1037610 | H42: ‡gvU †WweU t | K42: =N41+M41 -> 718950
A43: ‡gvU †WweU t | D43: =K42 -> 718950
A44: eZ©gvb K¨vk t | D44: =D42-D43 -> 318660

Sheet OCT (18)
A1: ‡gmvm© Imgvb wdm& | H1: ‡gmvm© Imgvb wdm&
A2: mvBb‡evW© evRvi grm Avor | H2: mvBb‡evW© evRvi grm Avor
A3: evi t | C3: ïµevi | D3: ‡µwWU | F3: ZvwiL t- | G3: 45583 | H3: evi t | J3: ïµevi | K3: ‡WwWU | M3: ZvwiL t- | N3: 45583
A4: c~‡e©i K¨vk-Bb-n¨vÛ t | F4: ='OCT (17)'!D44 -> 318660 | G4: **** | J4: Awdm LiP-- | K4: D | M4: 980 | N4: ****
C5: Kwgkb-- | D5: C | F5: 11610 | G5: =F4 -> 318660 | J5: eKwkm-- | K5: D | M5: 1210 | N5: =M4 -> 980
C6: gmwR`-- | D6: C | F6: 130 | G6: =G5+F5 -> 330270 | J6: ÷vd‡`i bv¯Ív-- | K6: D | M6: 300 | N6: =N5+M5 -> 2190
C7: mwgwZ-- | D7: C | F7: 130 | G7: =G6+F6 -> 330400 | I7: 352 | J7: ‡gv¯Í-- | K7: D | L7: 315 | M7: 32420 | N7: =N6+M6 -> 2490
C8: wbjy Rgv-- | D8: C | F8: 4000 | G8: =G7+F7 -> 330530 | I8: 353 | J8: eKzj-- | K8: D | L8: 324 | M8: 5220 | N8: =N7+M7 -> 34910
C9: ‡gv¯Í-- | D9: C | F9: 26700 | G9: =G8+F8 -> 334530 | I9: 354 | J9: wRKz-- | K9: D | L9: 321 | M9: 740 | N9: =N8+M8 -> 40130
C10: jyrdvi-- | D10: C | F10: 10000 | G10: =G9+F9 -> 361230 | I10: 355 | J10: ‡gvZv‡je-- | K10: D | L10: 316 | M10: 15470 | N10: =N9+M9 -> 40870
C11: wRKz-- | D11: C | F11: 50950 | G11: =G10+F10 -> 371230 | I11: 356 | J11: ‡mvnvM-- | K11: D | L11: 320 | M11: 1940 | N11: =N10+M10 -> 56340
C12: ‡mvnvM-- | D12: C | F12: 5500 | G12: =G11+F11 -> 422180 | I12: 357 | J12: jyrdvi-- | K12: D | L12: 322 | M12: 6450 | N12: =N11+M11 -> 58280
C13: ‡gvZv‡je-- | D13: C | F13: 20000 | G13: =G12+F12 -> 427680 | I13: 358 | J13: gyiv`-- | K13: D | L13: 326 | M13: 6150 | N13: =N12+M12 -> 64730
C14: gyiv`-- | D14: C | F14: 10000 | G14: =G13+F13 -> 447680 | I14: 359 | J14: AvwRRyj-- | K14: D | L14: 319 | M14: 74450 | N14: =N13+M13 -> 70880
C15: wØb eÜz-- | D15: C | F15: 5000 | G15: =G14+F14 -> 457680 | I15: 360 | J15: kvwKj-- | K15: D | L15: 342 | M15: 4050 | N15: =N14+M14 -> 145330
C16: my‡`e-- | D16: C | F16: 4110 | G16: =G15+F15 -> 462680 | I16: 361 | J16: Ggvg-- | K16: D | L16: 328 | M16: 17670 | N16: =N15+M15 -> 149380
C17: Kwig-- | D17: C | F17: 7900 | G17: =G16+F16 -> 466790 | I17: 362 | J17: AvwRRyj evRvi-- | K17: D | L17: 327 | M17: 1890 | N17: =N16+M16 -> 167050
C18: wgRvb-- | D18: C | F18: 4230 | G18: =G17+F17 -> 474690 | I18: 363 | J18: ‡ejv‡qZ-- | K18: D | L18: 328 | M18: 4460 | N18: =N17+M17 -> 168940
... C34: bM` weµq-- | D34: C | F34: 25560 | G34: =G33+F33 -> 544930 | I34: 379 | J34: KzÏym-- | K34: D | L34: 309 | M34: 2750 | N34: =N33+M33 -> 229330
G35: =G34+F34 -> 570490 | I35: 380 | J35: Gbmvb-- | K35: D | L35: 325 | M35: 1320 | N35: =N34+M34 -> 232080
G36: =G35+F35 -> 570490 | I36: 381 | J36: wgRvb-- | K36: D | L36: 331 | M36: 1650 | N36: =N35+M35 -> 233400
C37: AvR‡Ki evKx = 2,65,220/= | G37: =G36+F36 -> 570490 | I37: 382 | J37: Avmjvg-- | K37: D | L37: 329 | M37: 15550 | N37: =N36+M36 -> 235050
C38: AvR‡Ki Av`vq = 2,10,400/= | G38: =G37+F37 -> 570490 | I38: 383 | J38: kvwnb-- | K38: D | L38: 341 | M38: 16870 | N38: =N37+M37 -> 250600
G39: =G38+F38 -> 570490 | I39: 384 | J39: wMqvm-- | K39: D | L39: 310 | M39: 240 | N39: =N38+M38 -> 267470
G40: =G39+F39 -> 570490 | I40: 385 | J40: bM` weµq-- | K40: D | M40: 25560 | N40: =N39+M39 -> 267710
G41: =G40+F40 -> 570490 | N41: =N40+M40 -> 293270
J42: c~‡e©i LiP-30030/= | N42: =N41+M41 -> 293270
J43: AvR‡Ki LiP-2490/= | N43: =N42+M42 -> 293270
J44: ‡gvU LiP= 32520/= | N44: =N43+M43 -> 293270
A45: †gvU †µwWU t | D45: =G41+F41 -> 570490 | H45: ‡gvU †WweU t | K45: =N41+M41 -> 293270
A46: ‡gvU †WweU t | D46: =K45 -> 293270
A47: eZ©gvb K¨vk t | D47: =D45-D46 -> 277220

Sheet OCT (19)
A1: ‡gmvm© Imgvb wdm& | H1: ‡gmvm© Imgvb wdm&
A2: mvBb‡evW© evRvi grm Avor | H2: mvBb‡evW© evRvi grm Avor
A3: evi t | C3: kwbevi | D3: ‡µwWU | F3: ZvwiL t- | G3: 45584 | H3: evi t | J3: kwbevi | K3: ‡WwWU | M3: ZvwiL t- | N3: 45584
A4: c~‡e©i K¨vk-Bb-n¨vÛ t | F4: ='OCT (18)'!D47 -> 277220 | G4: **** | J4: Awdm LiP-- | K4: D | M4: 1010 | N4: ****
C5: Kwgkb-- | D5: C | F5: 12240 | G5: =F4 -> 277220 | J5: eKwkm-- | K5: D | M5: 1270 | N5: =M4 -> 1010
C6: gmwR`-- | D6: C | F6: 90 | G6: =G5+F5 -> 289460 | J6: ÷vd‡`i bv¯Ív-- | K6: D | M6: 350 | N6: =N5+M5 -> 2280
C7: mwgwZ-- | D7: C | F7: 90 | G7: =G6+F6 -> 289550 | I7: 386 | J7: iv¾vK-- | K7: D | L7: 356 | M7: 740 | N7: =N6+M6 -> 2630
C8: ‡mvnvM -- | D8: C | F8: 2000 | G8: =G7+F7 -> 289640 | I8: 387 | J8: ‡gv¯Í-- | K8: D | L8: 351 | M8: 20260 | N8: =N7+M7 -> 3370
C9: AvwRRyj-- | D9: C | F9: 20000 | G9: =G8+F8 -> 291640 | I9: 388 | J9: eKzj-- | K9: D | L9: 358 | M9: 4680 | N9: =N8+M8 -> 23630
C10: m`v-- | D10: C | F10: 210 | G10: =G9+F9 -> 311640 | I10: 389 | J10: wRKz-- | K10: D | L10: 349 | M10: 6020 | N10: =N9+M9 -> 28310
